<?xml version="1.0" ?>
<sdf version="1.5">
  <model name="turtlebot3_burger">
    <pose>0.0 0.0 0.0 0.0 0.0 0.0</pose>

    <link name="base_footprint">
        <inertial>
        <inertia>
          <ixx>1.6666666666666667e-09</ixx>
          <ixy>0.000</ixy>
          <ixz>0.000</ixz>
          <iyy>1.6666666666666667e-09</iyy>
          <iyz>0.000</iyz>
          <izz>1.6666666666666667e-09</izz>
        </inertia>
        <mass>0.01</mass>
      </inertial>

      <visual name="base_footprint_visual">
        <geometry>
          <box>
            <size>0.001 0.001 0.001</size>
          </box>
        </geometry>
      </visual>
    </link>

    <link name="base_link">

      <inertial>
        <pose>-0.032 0 0.070 0 0 0</pose>
        <inertia>
          <ixx>0.004319416666666666</ixx>
          <ixy>0.000</ixy>
          <ixz>0.000</ixz>
          <iyy>0.004081083333333333</iyy>
          <iyz>0.000</iyz>
          <izz>0.003412333333333333</izz>
        </inertia>
        <mass>1.0</mass>
      </inertial>

      <collision name="base_collision">
        <max_contacts>4</max_contacts>
        <pose>-0.032 0 0.070 0 0 0</pose>
        <geometry>
          <cylinder>
            <radius>0.07</radius>
            <length>0.14</length>
          </cylinder>
        </geometry>
        <surface>
          
          <friction>
            <ode>
              <mu>0.01</mu>
              <mu2>0.01</mu2>
              <fdir1>0 0 0</fdir1>
              <slip1>0.0</slip1>
              <slip2>0.0</slip2>
            </ode>
          </friction>
          <contact>
            <ode>
              <soft_cfm>0.001</soft_cfm>
              <soft_erp>0.2</soft_erp>
              <kp>1e+4</kp>
              <kd>1e+4</kd>
              <max_vel>0.01</max_vel>
              <min_depth>0.001</min_depth>
            </ode>
          </contact>
        </surface>
      </collision>

      <visual name="base_visual">
        <pose>-0.032 0 0 0 0 0</pose>
        <geometry>
          <mesh>
            <uri>model://turtlebot3_burger/meshes/burger_base_v2_single.dae</uri>
            <scale>0.001 0.001 0.001</scale>
          </mesh>
        </geometry>
      </visual>
    </link>

    <link name="imu_link">

      <inertial>
        <inertia>
          <ixx>1.6666666666666667e-09</ixx>
          <ixy>0.000</ixy>
          <ixz>0.000</ixz>
          <iyy>1.6666666666666667e-09</iyy>
          <iyz>0.000</iyz>
          <izz>1.6666666666666667e-09</izz>
        </inertia>
        <mass>0.01</mass>
      </inertial>

      <visual name="imu_link_visual">
        <geometry>
          <box>
            <size>0.001 0.001 0.001</size>
          </box>
        </geometry>
      </visual>

      <sensor name="tb3_imu" type="imu">
        <always_on>true</always_on>
        <update_rate>200</update_rate>
        <imu>
          <angular_velocity>
            <x>
              <noise type="gaussian">
                <mean>0.0</mean>
                <stddev>2e-4</stddev>
              </noise>
            </x>
            <y>
              <noise type="gaussian">
                <mean>0.0</mean>
                <stddev>2e-4</stddev>
              </noise>
            </y>
            <z>
              <noise type="gaussian">
                <mean>0.0</mean>
                <stddev>2e-4</stddev>
              </noise>
            </z>
          </angular_velocity>
          <linear_acceleration>
            <x>
              <noise type="gaussian">
                <mean>0.0</mean>
                <stddev>1.7e-2</stddev>
              </noise>
            </x>
            <y>
              <noise type="gaussian">
                <mean>0.0</mean>
                <stddev>1.7e-2</stddev>
              </noise>
            </y>
            <z>
              <noise type="gaussian">
                <mean>0.0</mean>
                <stddev>1.7e-2</stddev>
              </noise>
            </z>
          </linear_acceleration>
        </imu>
        <plugin name="turtlebot3_imu" filename="libgazebo_ros_imu_sensor.so">
          <ros>
            <!-- <namespace>/tb3_0</namespace> -->
            <remapping>~/out:=imu</remapping>
          </ros>
        </plugin>
      </sensor>
    </link>

    <link name="base_scan">
      <inertial>
        <pose>-0.020 0 0.161 0 0 0</pose>
        <inertia>
          <ixx>6.545677083333333e-05</ixx>
          <ixy>0.000</ixy>
          <ixz>0.000</ixz>
          <iyy>0.00010765708333333333</iyy>
          <iyz>0.000</iyz>
          <izz>0.00014110052083333332</izz>
        </inertia>
        <mass>0.125</mass>
      </inertial>

      <collision name="lidar_sensor_collision">
        <max_contacts>2</max_contacts>
        <pose>-0.020 0 0.161 0 0 0</pose>
        <geometry>
          <cylinder>
            <radius>0.0508</radius>
            <length>0.055</length>
          </cylinder>
        </geometry>
      </collision>

      <visual name="lidar_sensor_visual">
        <pose>-0.032 0 0.171 0 0 0</pose>
        <geometry>
          <mesh>
            <uri>model://turtlebot3_burger/meshes/lds_v2_single.dae</uri>
            <scale>0.001 0.001 0.001</scale>
          </mesh>
        </geometry>
      </visual>

      <sensor name="hls_lfcd_lds" type="ray">
        <always_on>true</always_on>
        <visualize>false</visualize>
        <pose>-0.032 0 0.171 0 0 0</pose>
        <update_rate>5</update_rate>
        <ray>
          <scan>
            <horizontal>
              <samples>660</samples>
              <!-- <resolution>0.500000</resolution> -->
              <min_angle>-3.1416</min_angle>
              <max_angle>3.1416</max_angle>
            </horizontal>
          </scan>
          <range>
            <min>0.120000</min>
            <max>30.0</max>
            <resolution>0.015000</resolution>
          </range>
          <noise>
            <type>gaussian</type>
            <mean>0.0</mean>
            <stddev>0.01</stddev>
          </noise>
        </ray>
        <plugin name="turtlebot3_laserscan" filename="libgazebo_ros_ray_sensor.so">
          <ros>
            <!-- <namespace>/tb3_0</namespace> -->
            <remapping>~/out:=scan</remapping>
          </ros>
          <output_type>sensor_msgs/LaserScan</output_type>
          <frame_name>base_scan</frame_name>
        </plugin>
      </sensor>
    </link>

    <!--  CAMERA -->
    <!--<link name="base_cam">
      <inertial>
        <pose>0.03566 0 0.104788 0 0 0</pose>
        <inertia>
          <ixx>6.545677083333333e-05</ixx>
          <ixy>0.000</ixy>
          <ixz>0.000</ixz>
          <iyy>0.00010765708333333333</iyy>
          <iyz>0.000</iyz>
          <izz>0.00014110052083333332</izz>
        </inertia>
        <mass>0.125</mass>
      </inertial>

      <visual name="cam_sensor_visual">
        <pose>0.03566 0 0.104788 0 0 0</pose>
        <geometry>
            <mesh>
            <uri>model://turtlebot3_burger/meshes/cam.dae</uri>
            <scale>1.0 1.0 1.0</scale>
            </mesh>
        </geometry>
      </visual>

        <sensor name="rgb_camera" type="camera">
            <pose>0.03566 0 0.104788 0 0 0</pose>
          <camera>
            <horizontal_fov>1.3962634</horizontal_fov>
            <image>
              <width>300</width>
              <height>300</height>
              <format>R8G8B8</format>
            </image>
            <clip>
              <near>0.01</near>
              <far>6.0</far>
            </clip>
          </camera>
          <plugin name="rgb_camera_controller" filename="libgazebo_ros_camera.so">
            <ros>
              
            </ros>
            <cameraName>rgb_camera</cameraName>
            <imageTopicName>image_raw</imageTopicName>
            <cameraInfoTopicName>camera_info</cameraInfoTopicName>
            <frameName>base_cam</frameName>
            <hackBaseline>0.07</hackBaseline>
          </plugin>
        </sensor>
    </link>-->

    <link name="wheel_left_link">

      <inertial>
        <pose>0 0.08 0.023 -1.57 0 0</pose>
        <inertia>
          <ixx>2.9925000000000002e-05</ixx>
          <ixy>0.000</ixy>
          <ixz>0.000</ixz>
          <iyy>2.9925000000000002e-05</iyy>
          <iyz>0.000</iyz>
          <izz>5.445000000000001e-05</izz>
        </inertia>
        <mass>0.1</mass>
      </inertial>

      <collision name="wheel_left_collision">
        <pose>0 0.08 0.023 -1.57 0 0</pose>
        <max_contacts>1</max_contacts>
        <geometry>
          <cylinder>
            <radius>0.033</radius>
            <length>0.001</length>
          </cylinder>
        </geometry>
        <surface>
          <!-- This friction pamareter don't contain reliable data!! -->
          <friction>
            <ode>
              <mu>10.0</mu>
              <mu2>10.0</mu2>
              <fdir1>0 0 0</fdir1>
              <slip1>0.0</slip1>
              <slip2>0.0</slip2>
            </ode>
          </friction>
          <contact>
            <ode>
              <soft_cfm>0.001</soft_cfm>
              <soft_erp>0.2</soft_erp>
              <kp>1e+4</kp>
              <kd>1e+4</kd>
              <max_vel>0.01</max_vel>
              <min_depth>0.001</min_depth>
            </ode>
          </contact>
        </surface>
      </collision>

      <visual name="wheel_left_visual">
        <pose>0 0.08 0.023 0 0 0</pose>
        <geometry>
          <mesh>
            <uri>model://turtlebot3_burger/meshes/left_tire_v2.dae</uri>
            <scale>0.001 0.001 0.001</scale>
          </mesh>
        </geometry>
      </visual>
    </link>

    <link name="wheel_right_link">

      <inertial>
        <pose>0.0 -0.08 0.023 -1.57 0 0</pose>
        <inertia>
          <ixx>2.9925000000000002e-05</ixx>
          <ixy>0.000</ixy>
          <ixz>0.000</ixz>
          <iyy>2.9925000000000002e-05</iyy>
          <iyz>0.000</iyz>
          <izz>5.445000000000001e-05</izz>
        </inertia>
        <mass>0.1</mass>
      </inertial>

      <collision name="wheel_right_collision">
        <pose>0.0 -0.08 0.023 -1.57 0 0</pose>
        <max_contacts>1</max_contacts>
        <geometry>
          <cylinder>
            <radius>0.033</radius>
            <length>0.001</length>
          </cylinder>
        </geometry>
        <surface>
          <!-- This friction pamareter don't contain reliable data!! -->
          <friction>
            <ode>
              <mu>10.0</mu>
              <mu2>10.0</mu2>
              <fdir1>0 0 0</fdir1>
              <slip1>0.0</slip1>
              <slip2>0.0</slip2>
            </ode>
          </friction>
          <contact>
            <ode>
              <soft_cfm>0.001</soft_cfm>
              <soft_erp>0.2</soft_erp>
              <kp>1e+4</kp>
              <kd>1e+4</kd>
              <max_vel>0.01</max_vel>
              <min_depth>0.001</min_depth>
            </ode>
          </contact>
        </surface>
      </collision>

      <visual name="wheel_right_visual">
        <pose>0.0 -0.08 0.023 0 0 0</pose>
        <geometry>
          <mesh>
            <uri>model://turtlebot3_burger/meshes/right_tire_v2.dae</uri>
            <scale>0.001 0.001 0.001</scale>
          </mesh>
        </geometry>
      </visual>
    </link>

    <link name='caster_back_link'>
      <pose>-0.081 0 -0.004 0 0 0</pose>
      <inertial>
        <mass>0.001</mass>
        <inertia>
          <ixx>1e-08</ixx>
          <ixy>0.000</ixy>
          <ixz>0.000</ixz>
          <iyy>1e-08</iyy>
          <iyz>0.000</iyz>
          <izz>1e-08</izz>
        </inertia>
      </inertial>
      <collision name='collision'>
        <max_contacts>1</max_contacts>
        <geometry>
          <sphere>
            <radius>0.005000</radius>
          </sphere>
        </geometry>
        <surface>
          <contact>
            <ode>
              <soft_cfm>0.001</soft_cfm>
              <soft_erp>0.2</soft_erp>
              <kp>1e+4</kp>
              <kd>1e+4</kd>
              <max_vel>0.01</max_vel>
              <min_depth>0.001</min_depth>
            </ode>
          </contact>
        </surface>
      </collision>
    </link>

    <joint name="base_joint" type="fixed">
      <parent>base_footprint</parent>
      <child>base_link</child>
      <pose>0.0 0.0 0.010 0 0 0</pose>
    </joint>

    <joint name="wheel_left_joint" type="revolute">
      <parent>base_link</parent>
      <child>wheel_left_link</child>
      <pose>0.0 0.08 0.023 -1.57 0 0</pose>
      <axis>
        <xyz>0 0 1</xyz>
      </axis>
    </joint>

    <joint name="wheel_right_joint" type="revolute">
      <parent>base_link</parent>
      <child>wheel_right_link</child>
      <pose>0.0 -0.08 0.023 -1.57 0 0</pose>
      <axis>
        <xyz>0 0 1</xyz>
      </axis>
    </joint>

    <joint name='caster_back_joint' type='ball'>
      <parent>base_link</parent>
      <child>caster_back_link</child>
    </joint>

    <joint name="imu_joint" type="fixed">
      <parent>base_link</parent>
      <child>imu_link</child>
      <pose>-0.032 0 0.068 0 0 0</pose>
      <axis>
        <xyz>0 0 1</xyz>
      </axis>
    </joint>

    <joint name="lidar_joint" type="fixed">
      <parent>base_link</parent>
      <child>base_scan</child>
      <pose>-0.032 0 0.171 0 0 0</pose>
      <axis>
        <xyz>0 0 1</xyz>
      </axis>
    </joint>

    <joint name="cam_joint" type="fixed">
      <parent>base_link</parent>
      <child>base_cam</child>
      <pose>0.0 0.0 1.0 0 0 0</pose>
    </joint>

    

    <plugin name="turtlebot3_diff_drive" filename="libgazebo_ros_diff_drive.so">

      <ros>
         <!-- <namespace>/tb3_0</namespace> -->
      </ros>

      <update_rate>30</update_rate>

      <!-- wheels -->
      <left_joint>wheel_left_joint</left_joint>
      <right_joint>wheel_right_joint</right_joint>

      <!-- kinematics -->
      <wheel_separation>0.160</wheel_separation>
      <wheel_diameter>0.066</wheel_diameter>

      <!-- limits -->
      <max_wheel_torque>20</max_wheel_torque>
      <max_wheel_acceleration>1.0</max_wheel_acceleration>

      <command_topic>cmd_vel</command_topic>

      <!-- output -->
      <publish_odom>true</publish_odom>
      <publish_odom_tf>true</publish_odom_tf>
      <publish_wheel_tf>false</publish_wheel_tf>

      <odometry_topic>odom</odometry_topic>
      <!--
      <odometry_frame>/tb3_0/odom</odometry_frame>
      <robot_base_frame>/tb3_0/base_footprint</robot_base_frame>
      -->
      <odometry_frame>odom</odometry_frame>
      <robot_base_frame>base_footprint</robot_base_frame>

    </plugin>

    <plugin name="turtlebot3_joint_state" filename="libgazebo_ros_joint_state_publisher.so">
      <ros>
        <!-- <namespace>/tb3_0</namespace> -->
        <remapping>~/out:=joint_states</remapping>
      </ros>
      <update_rate>30</update_rate>
      <joint_name>wheel_left_joint</joint_name>
      <joint_name>wheel_right_joint</joint_name>
    </plugin>      
  </model>
</sdf>
